Workbook

Sheet COVER
A1: PROJECT LUMINA
A5: AURA Consumer Sciences Ltd | IPO Valuation | FinOrbits IB Championship Season 1
A8: SUBMISSION DETAILS
A9: Participant Name | C9: Mukul Suyal
A11: College / Firm | C11: Galgotias University | BBA FIA | CFA Level I Candidate
A13: Submission Date | C13: April 2026
A17: COLOR LEGEND & USAGE GUIDE
A18: Blue bold text | C18: Input cells — type your assumptions here
A19: Black text | C19: Formula cells — calculated automatically, do not type
A20: Green text | C20: Cross-tab links — pulling from another sheet
A21: Light blue bg | C21: Assumption input cells — fill these in
A23: INSTRUCTIONS — READ BEFORE BUILDING
A24: Step 1 | Read the CIM (Project Lumina) and the FinOrbits IB Analyst Handbook completely.
A25: Step 2 | Go to PROJECTIONS tab. Enter your revenue, margin, and working capital assumptions in blue cells.
A26: Step 3 | Go to DCF tab. Enter all WACC inputs — research your own risk-free rate, ERP, beta, and cost of debt. All FCF rows are pre-structured.
A27: Step 4 | Go to COMPARABLES tab. Select your applied multiple and enter your premium/discount commentary.
A28: Step 5 | Complete SUMMARY tab. Fill valuation ranges, weights, and your final IPO recommendation.
A29: RULE: Never hardcode a number inside a formula cell. Blue = your input. Black = formula calculates.
A30: RULE: Every assumption must be justified in your Investment Memo submission.
A32: CONFIDENTIAL | Project Lumina | FinOrbits IB Championship S1 | finorbits.com

Sheet HISTORICAL
A1: HISTORICAL FINANCIALS — AURA CONSUMER SCIENCES LTD
A5: READ-ONLY | Sourced from AURA audited financials. Do not edit.
A7: INCOME STATEMENT (₹ Crore)
A8: ₹ Crore | B8: FY2022A | C8: FY2023A | D8: FY2024A
A9: Revenue | B9: 112 | C9: 163 | D9: 224
A10: COGS | B10: -67.2 | C10: -95.4 | D10: -126
A11: Gross Profit | B11: =B9+B10 -> 44.8 | C11: =C9+C10 -> 67.6 | D11: =D9+D10 -> 98
A12: Gross Margin % | B12: =B11/B9 -> 0.4 | C12: =C11/C9 -> 0.41472393 | D12: =D11/D9 -> 0.4375
A13: EBITDA | B13: 8.4 | C13: 16.3 | D13: 26.9
A14: EBITDA Margin % | B14: =B13/B9 -> 0.075 | C14: =C13/C9 -> 0.1 | D14: =D13/D9 -> 0.12008929
A15: D&A | B15: -1.2 | C15: -1.7 | D15: -2.6
A16: EBIT | B16: 7.2 | C16: 14.6 | D16: 24.3
A17: Other Income | B17: 0.3 | C17: 0.4 | D17: 0.5
A18: Interest Expense | B18: -1.8 | C18: -2.5 | D18: -3.2
A19: PBT | B19: 5.7 | C19: 12.5 | D19: 21.6
A20: Tax (25%) | B20: -3.6 | C20: -6 | D20: -8.2
A21: PAT | B21: 2.1 | C21: 6.5 | D21: 13.4
A22: PAT Margin % | B22: =B21/B9 -> 0.01875 | C22: =C21/C9 -> 0.039877301 | D22: =D21/D9 -> 0.059821429
A25: BALANCE SHEET (₹ Crore)
A26: ₹ Crore | B26: FY2022A | C26: FY2023A | D26: FY2024A
A27: ASSETS
A28: Fixed Assets (Net) | B28: 65 | C28: 89 | D28: 112
A29: Inventories | B29: 18 | C29: 24 | D29: 31
A30: Trade Receivables | B30: 12 | C30: 16.5 | D30: 22
A31: Cash & Equivalents | B31: 14 | C31: 21 | D31: 28
A32: Other Current Assets | B32: 5 | C32: 6.5 | D32: 5
A33: TOTAL ASSETS | B33: =B28+B29+B30+B31+B32 -> 114 | C33: =C28+C29+C30+C31+C32 -> 157 | D33: =D28+D29+D30+D31+D32 -> 198
A34: LIABILITIES & EQUITY
A35: Long-Term Debt | B35: 22 | C35: 31 | D35: 42
A36: Trade Payables | B36: 15 | C36: 19 | D36: 26
A37: Other Liabilities | B37: 8 | C37: 10 | D37: 18
A38: Total Equity | B38: 69 | C38: 97 | D38: 112
A39: TOTAL L & E | B39: =B35+B36+B37+B38 -> 114 | C39: =C35+C36+C37+C38 -> 157 | D39: =D35+D36+D37+D38 -> 198
A42: KEY FINANCIAL RATIOS
A43: Ratio | B43: FY2022A | C43: FY2023A | D43: FY2024A
A44: Revenue Growth YoY | B44: - | C44: =C9/B9-1 -> 0.45535714 | D44: =D9/C9-1 -> 0.37423313
A45: EBITDA Margin | B45: =B13/B9 -> 0.075 | C45: =C13/C9 -> 0.1 | D45: =D13/D9 -> 0.12008929
A46: Debt/Equity Ratio | B46: =B35/B38 -> 0.31884058 | C46: =C35/C38 -> 0.31958763 | D46: =D35/D38 -> 0.375
A47: Interest Coverage | B47: =B16/ABS(B18) -> 4 | C47: =C16/ABS(C18) -> 5.84 | D47: =D16/ABS(D18) -> 7.59375
A48: Return on Equity | B48: =B21/B38 -> 0.030434783 | C48: =C21/C38 -> 0.067010309 | D48: =D21/D38 -> 0.11964286
...

Sheet ASSUMPTIONS
B1: VALUES & BASIS OF ASSUMPTION — PROJECT LUMINA | AURA Consumer Sciences Ltd
B2: Complete this sheet before submitting your model. Every blue assumption in PROJECTIONS and DCF VALUATION must have a documented value (col D) and written justification (col E). Graders will evaluate this sheet independently.
B3: Assumption | C3: Your Value (Blue = Input) | D3: Basis of Assumption — Write Clearly (This is Graded)
B4: SECTION 1 — INCOME STATEMENT ASSUMPTIONS (PROJECTIONS sheet)
B5: Revenue Growth Rate % | C5: 30%(FY25), 27%(FY26), 24%(FY27), 21%(FY28), 18%(FY29) | D5: AURA FY22-24 CAGR 41.4%. D2C wellness sector 19% CAGR through FY28 (CIM). Tapering 30%→18% reflects base effect and competition. Conservative vs extrapolation. Sector CAGR = floor.
B6: Gross Margin % | C6: 44.5% → 46.3% | D6: Historical 40%→43.8% (+380bps). D2C +400-500bps premium. Protein (52% GM) lifts blended. Conservative ceiling 46.3%.
B7: EBITDA Margin % | C7: 13.0% → 14.8% | D7: Mgmt guidance 13%+ FY25. Historical +250bps/2yr from fixed-cost leverage. Peer Mamaearth 14-15%. 14.8% FY29 achievable with Tier-2 scale.
B8: D&A as % of Revenue | C8: 1.2% FY25-26; declining to 1.0% FY29 | D8: Historical D&A 1.07-1.16% of revenue. Asset-light (contract mfg). D&A% declines as revenue grows faster than fixed assets.
B9: Tax Rate % | C9: 25.0% all years | D9: 25% per CIM Income Statement. Applied per CIM Technical Note #1 uniformly. No documented reason to deviate.
B10: Capex as % of Revenue | C10: 3.5% FY25-26; 4.0% FY27; 3.8% FY28; 3.5% FY29 | D10: Capex not in CIM. Asset-light forward model: 3.5-4% funds Tier-2/3 logistics infra only. Peak FY27 for expansion rollout.
B11: SECTION 2 — WORKING CAPITAL ASSUMPTIONS (PROJECTIONS sheet)
B12: Debtor Days (Receivables) | C12: 36 → 32 days | D12: CIM Key Risks: receivables ~36 days. 68% D2C = cash-advance. Gradual improvement to 32 days FY29. Formula: Receivables/Revenue×365.
B13: Creditor Days (Payables) | C13: 75 → 78 days | D13: Derived FY24: Payables Rs.26Cr / COGS Rs.126Cr × 365 = 75.3 days. COGS denominator per CIM Tech Note #2. Slight stretch 75→78.
B14: Inventory Days | C14: 50 → 46 days | D14: CIM Key Risks: ~50 inventory days. Used CIM-stated figure. Improving to 46 FY29 via cold-chain efficiency. Formula: Inv/COGS×365.
B15: SECTION 3 — INTEREST EXPENSE (PROJECTIONS sheet)
B16: Interest Expense FY2025E onward | C16: Rs.-1.1Cr(FY25) → Rs.-1.7Cr(FY29) | D16: Post-IPO Rs.30Cr repaid (CIM TxSummary): LTD Rs.42→Rs.12Cr. Kd=3.2/36.5=8.8%~9% (CIM Tech Note #3). FY25:9%×12=Rs.1.1Cr. Re-levering for Tier-2 expansion.
B17: SECTION 4 — WACC ASSUMPTIONS (DCF VALUATION sheet)
B18: Risk-Free Rate (Rf) | C18: 7.20% | D18: India 10-yr G-Sec yield April 2026. Source: RBI.org.in / CCIL published G-Sec rates.
B19: Equity Risk Premium (ERP) | C19: 8.10% | D19: Damodaran India ERP January 2026. Source: pages.stern.nyu.edu/~adamodar.
B20: Beta (Levered) | C20: 1.15 | D20: Peer unlevered beta median 0.95 (Mamaearth,Bikaji,Emami,HindustanFoods,PatanjaliFoods). Re-levered at post-IPO D/E=0.021: BL=0.95×(1+0.75×0.021)=0.965. Small-cap premium → 1.15.
B21: Cost of Debt (pre-tax Kd) | C21: 9.0% | D21: CIM Tech Note #3: Int/Avg(OpeningLTD,ClosingLTD). FY24: Rs.3.2Cr/Rs.36.5Cr=8.77%. Rounded to 9.0%.
B22: Debt Weight D/V | C22: 17.5% | D22: Post-IPO LTD Rs.12Cr. Est. mkt cap Rs.600Cr+. D/V=1.96%. Used 17.5% conservatively for medium-term re-levering target.
B23: SECTION 5 — TERMINAL VALUE (DCF VALUATION sheet)
B24: Terminal Growth Rate (g) | C24: 6.5% | D24: India nominal long-run GDP ~6.5% (real ~5%+CPI ~4%-buffer). Strictly < WACC 14.1%. CIM: near-term sector growth NOT appropriate for TV.
B25: SECTION 6 — EV-TO-EQUITY BRIDGE (DCF VALUATION sheet)
B26: Net Debt | C26: Rs.-16Cr (net cash, post-IPO) | D26: FY24: LTD Rs.42Cr-Cash Rs.28Cr=Rs.14Cr pre-IPO. Rs.30Cr repaid (CIM TxSummary)->LTD=Rs.12Cr. Post-IPO: 12-28=-Rs.16Cr (net cash). Net cash adds to equity value.
B27: Shares Outstanding | C27: 10 Crore (pre-IPO, pre-filled) | D27: CIM Transaction Summary: 10 Crore pre-IPO shares. Pre-dilution basis. ~4Cr new shares from Rs.200Cr fresh issue at mid-band will dilute post-listing.
B28: SECTION 7 — COMPARABLES: APPLIED MULTIPLES (COMPARABLES sheet)
B29: Peer Company Selection Rationale | C29: Mamaearth, Bikaji Foods, Hindustan Foods, Emami, Patanjali Foods | D29: (1) Mamaearth: D2C FMCG, 22% growth, brand-led — most direct comparable. (2) Bikaji: premium Indian food brand, similar consumer. (3) Hindustan Foods: FMCG at lower scale. (4) Emami: established health/wellness — mature multiple anchor. (5) Patanjali Foods: Indian wellness brand. All NSE/BSE listed. Data: NSE/BSE market data + annual reports.
B30: EV/Revenue Multiple Applied | C30: 6.5x (vs peer median ~3.7x) | D30: 6.5x justified by pure-play D2C model, 30% rev growth (vs peer avg 15%), structural GM advantage. Comparable to Mamaearth listing multiple.
B31: EV/EBITDA Multiple Applied | C31: 38.0x (vs peer median ~37x) | D31: 38.0x = ~3% premium to peer median 37x. AURA's 30% growth vs peer avg 15% justifies small premium. Discounted for smaller scale. Conservative.
B32: P/E Multiple Applied | C32: 37.0x (= peer median) | D32: 37.0x = at peer median. PAT margins expanding but below peers on absolute basis. At-median appropriate given growth vs scale trade-off.
B34: CONFIDENTIAL | Project Lumina | FinOrbits IB Simulation Season 1 | finorbits.com

Sheet PROJECTIONS
A1: PROJECTIONS — FY2025E | FY2026E | FY2027E | FY2028E | FY2029E
A5: Enter assumptions in BLUE cells only. Every assumption must be justified in your Investment Memo. All projection years (FY2025E–FY2029E) are fully analyst-driven — no figures are pre-given. Refer to the CIM Analyst Guidance for reference points.
A7: SECTION 1 — KEY ASSUMPTIONS (Blue = your inputs)
A8: Assumption | B8: FY2025E | C8: FY2026E | D8: FY2027E | E8: FY2028E | F8: FY2029E | G8: Basis of assumption
A9: Revenue Growth Rate % | B9: 0.3 | C9: 0.27 | D9: 0.24 | E9: 0.21 | F9: 0.18 | G9: AURA FY22-24 CAGR=41.4%. D2C wellness sector 19% CAGR (CIM). Tapering 30%→18% (FY25-29) for base effect and competition (Mamaearth, ITC YogaBar, 1200+ brands). Conservative; sector CAGR = floor.
A10: Gross Margin % | B10: 0.445 | C10: 0.45 | D10: 0.455 | E10: 0.46 | F10: 0.463 | G10: Historical 40%→43.8% (+380bps FY22-24). D2C channel premium +400-500bps. Protein (52%GM) lifts blended. Conservative ceiling 46.3%.
A11: EBITDA Margin % | B11: 0.13 | C11: 0.135 | D11: 0.14 | E11: 0.145 | F11: 0.148 | G11: Mgmt guidance 13%+ FY25 (CIM). +250bps/2yr from fixed-cost leverage. Peer Mamaearth 14-15%. 14.8% FY29 achievable.
A12: D&A as % of Revenue | B12: 0.012 | C12: 0.012 | D12: 0.011 | E12: 0.011 | F12: 0.01 | G12: Historical D&A 1.07-1.16% of rev. Asset-light (contract mfg). D&A% declines as rev grows faster than fixed assets.
A13: Tax Rate % | B13: 0.25 | C13: 0.25 | D13: 0.25 | E13: 0.25 | F13: 0.25 | G13: 25% per CIM. CIM Technical Note #1: apply 25% on PBT uniformly. No deviation basis.
A14: Capex as % of Revenue | B14: 0.035 | C14: 0.035 | D14: 0.04 | E14: 0.038 | F14: 0.035 | G14: Capex not disclosed in CIM. Forward: asset-light model. 3.5-4% for Tier-2/3 logistics only (no mfg). Peak FY27 for expansion.
A15: Debtor Days | B15: 36 | C15: 35 | D15: 34 | E15: 33 | F15: 32 | G15: CIM Key Risks: receivables ~36 days. 68% D2C = cash-advance. Gradual improvement to 32 days FY29. Formula: Rec/Rev×365.
A16: Creditor Days | B16: 75 | C16: 75 | D16: 76 | E16: 77 | F16: 78 | G16: Derived FY24: Payables Rs.26Cr / COGS Rs.126Cr × 365 = 75.3 days. CIM Tech Note #2: COGS denominator. Slight stretch 75→78.
A17: Inventory Days | B17: 50 | C17: 50 | D17: 48 | E17: 47 | F17: 46 | G17: CIM Key Risks states inventory ~50 days. Maintained FY25-26; improving to 46 FY29 via cold-chain efficiency. Formula: Inv/COGS×365.
A19: SECTION 2 — PROJECTED INCOME STATEMENT (₹ Crore)
A20: ₹ Crore | B20: FY2022A | C20: FY2023A | D20: FY2024A | E20: FY2025E | F20: FY2026E | G20: FY2027E | H20: FY2028E | I20: FY2029E
A21: Revenue | B21: 112 | C21: 163 | D21: 224 | E21: =D21*(1+B9) -> 291.2 | F21: =E21*(1+C9) -> 369.824 | G21: =F21*(1+D9) -> 458.58176 | H21: =G21*(1+E9) -> 554.88393 | I21: =H21*(1+F9) -> 654.76304
A22: COGS | B22: -67.2 | C22: -95.4 | D22: -126 | E22: =-E21*(1-B10) -> -161.616 | F22: =-F21*(1-C10) -> -203.4032 | G22: =-G21*(1-D10) -> -249.92706 | H22: =-H21*(1-E10) -> -299.63732 | I22: =-I21*(1-F10) -> -351.60775
A23: Gross Profit | B23: 44.8 | C23: 67.6 | D23: 98 | E23: =E21+E22 -> 129.584 | F23: =F21+F22 -> 166.4208 | G23: =G21+G22 -> 208.6547 | H23: =H21+H22 -> 255.24661 | I23: =I21+I22 -> 303.15529
A24: Gross Margin % | B24: 0.4 | C24: 0.415 | D24: 0.438 | E24: =E23/E21 -> 0.445 | F24: =F23/F21 -> 0.45 | G24: =G23/G21 -> 0.455 | H24: =H23/H21 -> 0.46 | I24: =I23/I21 -> 0.463
A25: EBITDA | B25: 8.4 | C25: 16.3 | D25: 26.9 | E25: =E21*B11 -> 37.856 | F25: =F21*C11 -> 49.92624 | G25: =G21*D11 -> 64.201446 | H25: =H21*E11 -> 80.45817 | I25: =I21*F11 -> 96.904929
A26: EBITDA Margin % | B26: 0.075 | C26: 0.1 | D26: 0.12 | E26: =E25/E21 -> 0.13 | F26: =F25/F21 -> 0.135 | G26: =G25/G21 -> 0.14 | H26: =H25/H21 -> 0.145 | I26: =I25/I21 -> 0.148
A27: D&A | B27: -1.2 | C27: -1.7 | D27: -2.6 | E27: =-E21*B12 -> -3.4944 | F27: =-F21*C12 -> -4.437888 | G27: =-G21*D12 -> -5.0443994 | H27: =-H21*E12 -> -6.1037232 | I27: =-I21*F12 -> -6.5476304
A28: EBIT | B28: 7.2 | C28: 14.6 | D28: 24.3 | E28: =E25+E27 -> 34.3616 | F28: =F25+F27 -> 45.488352 | G28: =G25+G27 -> 59.157047 | H28: =H25+H27 -> 74.354447 | I28: =I25+I27 -> 90.357299
A29: Interest Expense | B29: -1.8 | C29: -2.5 | D29: -3.2 | E29: -1.1 | F29: -1.2 | G29: -1.4 | H29: -1.5 | I29: -1.7 | J29: Post-IPO Rs.30Cr repaid (CIM TxSummary). LTD Rs.42→Rs.12Cr. Kd=3.2/36.5=8.8%~9%. FY25:9%×12=Rs.1.1Cr. Gradual re-levering for Tier-2 expansion.
A30: PBT | B30: 5.7 | C30: 12.5 | D30: 21.6 | E30: =E28+E29 -> 33.2616 | F30: =F28+F29 -> 44.288352 | G30: =G28+G29 -> 57.757047 | H30: =H28+H29 -> 72.854447 | I30: =I28+I29 -> 88.657299
A31: Tax | B31: -3.6 | C31: -6 | D31: -8.2 | E31: =-E30*B13 -> -8.3154 | F31: =-F30*C13 -> -11.072088 | G31: =-G30*D13 -> -14.439262 | H31: =-H30*E13 -> -18.213612 | I31: =-I30*F13 -> -22.164325
A32: PAT | B32: 2.1 | C32: 6.5 | D32: 13.4 | E32: =E30+E31 -> 24.9462 | F32: =F30+F31 -> 33.216264 | G32: =G30+G31 -> 43.317785 | H32: =H30+H31 -> 54.640835 | I32: =I30+I31 -> 66.492974
A33: PAT Margin % | B33: =B32/B21 -> 0.01875 | C33: =C32/C21 -> 0.039877301 | D33: =D32/D21 -> 0.059821429 | E33: =E32/E21 -> 0.085666896 | F33: =F32/F21 -> 0.08981641 | G33: =G32/G21 -> 0.094460332 | H33: =H32/H21 -> 0.098472549 | I33: =I32/I21 -> 0.10155273
A35: SECTION 3 — WORKING CAPITAL SCHEDULE (₹ Crore)
A36: ₹ Crore | B36: FY2022A | C36: FY2023A | D36: FY2024A | E36: FY2025E | F36: FY2026E | G36: FY2027E | H36: FY2028E | I36: FY2029E
A37: Inventories = Revenue × Inventory Days / 365 | B37: 18 | C37: 24 | D37: 31 | E37: =E21*B17/365 -> 39.890411 | F37: =F21*C17/365 -> 50.660822 | G37: =G21*D17/365 -> 60.306642 | H37: =H21*E17/365 -> 71.450807 | I37: =I21*F17/365 -> 82.518081 | J37: Formula: = Revenue x Inv Days / 365
A38: Trade Receivables = Revenue × Debtor Days / 365 | B38: 12 | C38: 16.5 | D38: 22 | E38: =E21*B15/365 -> 28.721096 | F38: =F21*C15/365 -> 35.462575 | G38: =G21*D15/365 -> 42.717205 | H38: =H21*E15/365 -> 50.167588 | I38: =I21*F15/365 -> 57.403883 | J38: Formula: = Revenue x Debtor Days / 365
A39: Trade Payables = COGS × Creditor Days / 365 | B39: 15 | C39: 19 | D39: 26 | E39: =ABS(E22)*B16/365 -> 33.208767 | F39: =ABS(F22)*C16/365 -> 41.795178 | G39: =ABS(G22)*D16/365 -> 52.039607 | H39: =ABS(H22)*E16/365 -> 63.211161 | I39: =ABS(I22)*F16/365 -> 75.138095 | J39: Formula: = ABS(COGS) x Creditor Days / 365
A40: Net Working Capital = Inventories + Receivables − Payables | B40: 15 | C40: 21.5 | D40: 27 | E40: =E37+E38-E39 -> 35.40274 | F40: =F37+F38-F39 -> 44.328219 | G40: =G37+G38-G39 -> 50.984241 | H40: =H37+H38-H39 -> 58.407234 | I40: =I37+I38-I39 -> 64.783869 | J40: Inventories + Receivables minus Payables
A41: Change in WC = Net WC(t) − Net WC(t−1) ← link this row to DCF | B41: — | C41: 6.5 | D41: 5.5 | E41: =E40-D40 -> 8.4027397 | F41: =F40-E40 -> 8.9254795 | G41: =G40-F40 -> 6.6560214 | H41: =H40-G40 -> 7.4229938 | I41: =I40-H40 -> 6.3766349 | J41: Positive delta WC = cash outflow. Deduct in FCF.
A43: SECTION 4 — INTEREST EXPENSE ASSUMPTION
A44: Crore | B44: FY2022A | C44: FY2023A | D44: FY2024A | E44: FY2025E | F44: FY2026E | G44: FY2027E | H44: FY2028E | I44: FY2029E
A45: Interest Expense | B45: -1.8 | C45: -2.5 | D45: -3.2 | E45: -1.1 | F45: -1.2 | G45: -1.4 | H45: -1.5 | I45: -1.7
A48: CONFIDENTIAL | Project Lumina | FinOrbits IB Championship S1

Sheet DCF VALUATION
A1: DCF VALUATION — DISCOUNTED CASH FLOW ANALYSIS
A6: SECTION 1 — WACC CALCULATION
A7: Component | B7: Value | C7: Notes
A8: Risk-Free Rate (10-yr G-Sec) | B8: 0.072 | C8: India 10-yr G-Sec 7.20% — RBI.org.in, April 2026
A9: Equity Risk Premium (ERP) | B9: 0.081 | C9: Damodaran India ERP 8.10% — stern.nyu.edu/~adamodar, Jan 2026 dataset
A10: Beta (Levered) | B10: 1.15 | C10: Peer unlev. beta median 0.95 (Mamaearth,Bikaji,Emami,HindustanFoods,PatanjaliFoods). Re-levered at post-IPO D/E=0.021: BL=0.965. Small-cap premium added → 1.15
A11: Cost of Equity (CAPM) | B11: =B8+(B10*B9) -> 0.16515 | C11: = Rf + Beta x ERP. Auto-calculated.
A12: Cost of Debt (pre-tax) | B12: 0.09 | C12: Derived: FY24 Int Rs.3.2Cr / Avg(31+42)/2=36.5Cr = 8.77%. Rounded 9.0%. CIM Tech Note #3.
A13: Tax Rate | B13: 0.25 | C13: 25% per CIM. CIM Technical Note #1.
A14: After-tax Cost of Debt | B14: =B12*(1-B13) -> 0.0675 | C14: = Kd x (1-t). Auto-calculated.
A15: Debt Weight (D/V) | B15: 0.175 | C15: Post-IPO LTD Rs.12Cr. Est. mkt cap Rs.600Cr+. D/V=12/612=1.96%. Used 17.5% conservatively for medium-term re-levering.
A16: Equity Weight (E/V) | B16: =1-B15 -> 0.825
A17: WACC | B17: =B11*B16+B14*B15 -> 0.14806125 | C17: = Ke x (E/V) + Kd(1-t) x (D/V). Your discount rate.
A19: SECTION 2 — FREE CASH FLOW (FCFF) | FY2025E-FY2029E
A20: ₹ Crore | B20: FY2025E | C20: FY2026E | D20: FY2027E | E20: FY2028E | F20: FY2029E
A21: EBIT (from your Projections tab) | B21: =PROJECTIONS!E28 -> 34.3616 | C21: =PROJECTIONS!F28 -> 45.488352 | D21: =PROJECTIONS!G28 -> 59.157047 | E21: =PROJECTIONS!H28 -> 74.354447 | F21: =PROJECTIONS!I28 -> 90.357299
A22: (-) Tax on EBIT = EBIT x Tax Rate | B22: =-B21*B13 -> -8.5904 | C22: =-C21*B13 -> -11.372088 | D22: =-D21*B13 -> -14.789262 | E22: =-E21*B13 -> -18.588612 | F22: =-F21*B13 -> -22.589325
A23: NOPAT = EBIT x (1 - Tax Rate) | B23: =B21+B22 -> 25.7712 | C23: =C21+C22 -> 34.116264 | D23: =D21+D22 -> 44.367785 | E23: =E21+E22 -> 55.765835 | F23: =F21+F22 -> 67.767974
A24: (+) D&A (add back) | B24: =ABS(PROJECTIONS!E27) -> 3.4944 | C24: =ABS(PROJECTIONS!F27) -> 4.437888 | D24: =ABS(PROJECTIONS!G27) -> 5.0443994 | E24: =ABS(PROJECTIONS!H27) -> 6.1037232 | F24: =ABS(PROJECTIONS!I27) -> 6.5476304
A25: (-) Capex (cash outflow) | B25: =-PROJECTIONS!E21*PROJECTIONS!B14 -> -10.192 | C25: =-PROJECTIONS!F21*PROJECTIONS!C14 -> -12.94384 | D25: =-PROJECTIONS!G21*PROJECTIONS!D14 -> -18.34327 | E25: =-PROJECTIONS!H21*PROJECTIONS!E14 -> -21.085589 | F25: =-PROJECTIONS!I21*PROJECTIONS!F14 -> -22.916706
A26: (-) Change in Working Capital | B26: =-PROJECTIONS!E41 -> -8.4027397 | C26: =-PROJECTIONS!F41 -> -8.9254795 | D26: =-PROJECTIONS!G41 -> -6.6560214 | E26: =-PROJECTIONS!H41 -> -7.4229938 | F26: =-PROJECTIONS!I41 -> -6.3766349
A27: FREE CASH FLOW TO FIRM (FCFF) | B27: =B23+B24+B25+B26 -> 10.67086 | C27: =C23+C24+C25+C26 -> 16.684833 | D27: =D23+D24+D25+D26 -> 24.412893 | E27: =E23+E24+E25+E26 -> 33.360975 | F27: =F23+F24+F25+F26 -> 45.022263
A28: PV Factor = 1 / (1+WACC)^n | B28: =1/(1+B17)^1 -> 0.87103367 | C28: =1/(1+B17)^2 -> 0.75869965 | D28: =1/(1+B17)^3 -> 0.66085294 | E28: =1/(1+B17)^4 -> 0.57562516 | F28: =1/(1+B17)^5 -> 0.50138889
A29: Present Value of FCF | B29: =B27*B28 -> 9.2946785 | C29: =C27*C28 -> 12.658777 | D29: =D27*D28 -> 16.133332 | E29: =E27*E28 -> 19.203416 | F29: =F27*F28 -> 22.573663
A31: GUIDANCE: Link EBIT and D&A from your PROJECTIONS Income Statement. Capex = Revenue × Capex%. Change in Working Capital from your PROJECTIONS Working Capital Schedule. Note: FCF uses FCFF method — interest expense is excluded from the FCF build (it sits in the IS only).
A33: SECTION 3 — TERMINAL VALUE
A34: Item | B34: Value | C34: Notes
A35: Terminal Growth Rate (g) | B35: 0.065 | C35: India nominal long-run GDP ~6.5% (real ~5%+CPI~4%-buffer). Strictly < WACC 14.1%. Near-term sector growth (19%) NOT appropriate for TV (CIM guidance).
A36: Terminal Year FCFF (FY2029E) | B36: =F27 -> 45.022263 | C36: FY2029E FCFF linked from Section 2 row 27 col F above.
A37: Terminal Value = FCFF x (1+g) / (WACC-g) | B37: =B36*(1+B35)/(B17-B35) -> 577.26931 | C37: Gordon Growth Model: TV = Terminal FCFF × (1+g) / (WACC - g). Use your WACC and terminal growth inputs above.
A38: Discount Factor (Year 5) | B38: =1/(1+B17)^5 -> 0.50138889 | C38: = 1/(1+WACC)^5
A39: PV of Terminal Value | B39: =B37*B38 -> 289.43642 | C39: Terminal Value × Discount Factor. Should be ~60-75% of total EV.
A42: SECTION 4 — EV TO EQUITY VALUE BRIDGE
A43: Item | B43: ₹ Crore | C43: Notes
A44: Sum of PV of FCFs (Years 1-5) | B44: =SUM(B29:F29) -> 79.863866 | C44: Sum of PV FCF from Section 2 above
A45: (+) PV of Terminal Value | B45: =B39 -> 289.43642 | C45: Link from the PV of Terminal Value you calculated in Section 3 above.
A46: Enterprise Value (EV) | B46: =B44+B45 -> 369.30029 | C46: = Sum of above two rows
A47: (-) Net Debt | B47: -16 | C47: POST-IPO: FY24 LTD Rs.42Cr-Cash Rs.28Cr=Rs.14Cr pre-IPO. Rs.30Cr repaid (CIM TxSummary)->LTD=Rs.12Cr. Post-IPO NetDebt=12-28=-Rs.16Cr (net cash). Net cash ADDS to equity value.
A48: Equity Value | B48: =B46-B47 -> 385.30029 | C48: = EV minus Net Debt
A49: Shares Outstanding (crore) | B49: 10 | C49: Pre-filled. Do not change.
...

Sheet COMPARABLES
A1: TRADING COMPARABLES — PEER GROUP ANALYSIS
A6: Company (Research & Enter Your Own Peers) | B6: Mkt Cap (₹cr) | C6: EV (₹cr) | D6: Revenue (₹cr) | E6: EBITDA (₹cr) | F6: EV/Revenue | G6: EV/EBITDA | H6: P/E | I6: Rev Growth % | J6: EBITDA Margin %
A7: Honasa Consumer (Mamaearth) | B7: 11500 | C7: 10780 | D7: 1800 | E7: 225 | F7: 5.99 | G7: 47.9 | H7: 85 | I7: 0.22 | J7: 0.125
A8: Bikaji Foods International | B8: 12800 | C8: 12760 | D8: 1680 | E8: 208 | F8: 7.6 | G8: 61.3 | H8: 61 | I8: 0.18 | J8: 0.124
A9: Hindustan Foods Ltd | B9: 2900 | C9: 2920 | D9: 980 | E9: 78 | F9: 2.98 | G9: 37.4 | H9: 37 | I9: 0.15 | J9: 0.08
A10: Emami Ltd | B10: 15200 | C10: 14000 | D10: 3800 | E10: 760 | F10: 3.68 | G10: 18.4 | H10: 18 | I10: 0.08 | J10: 0.2
A11: Patanjali Foods Ltd | B11: 7400 | C11: 7170 | D11: 3600 | E11: 324 | F11: 1.99 | G11: 22.1 | H11: 22 | I11: 0.12 | J11: 0.09
A13: PEER STATISTICS — Auto-calculated once you enter peer data above (Median = base case | Lower Q = bear | Upper Q = bull)
A14: Metric | C14: Peer Median | D14: Peer Mean | E14: Lower Quartile | F14: Upper Quartile
A15: EV/Revenue | C15: =MEDIAN(F7:F11) -> 3.68 | D15: =AVERAGE(F7:F11) -> 4.448 | E15: =QUARTILE(F7:F11,1) -> 2.98 | F15: =QUARTILE(F7:F11,3) -> 5.99
A16: EV/EBITDA | C16: =MEDIAN(G7:G11) -> 37.4 | D16: =AVERAGE(G7:G11) -> 37.42 | E16: =QUARTILE(G7:G11,1) -> 22.1 | F16: =QUARTILE(G7:G11,3) -> 47.9
A17: P/E | C17: =MEDIAN(H7:H11) -> 37 | D17: =AVERAGE(H7:H11) -> 44.6 | E17: =QUARTILE(H7:H11,1) -> 22 | F17: =QUARTILE(H7:H11,3) -> 61
A18: Revenue Growth | C18: =MEDIAN(I7:I11) -> 0.15 | D18: =AVERAGE(I7:I11) -> 0.15 | E18: =QUARTILE(I7:I11,1) -> 0.12 | F18: =QUARTILE(I7:I11,3) -> 0.18
A19: EBITDA Margin | C19: =MEDIAN(J7:J11) -> 0.124 | D19: =AVERAGE(J7:J11) -> 0.1238 | E19: =QUARTILE(J7:J11,1) -> 0.09 | F19: =QUARTILE(J7:J11,3) -> 0.125
A20: Peer Selection Rationale (explain why each company is a relevant comparable for AURA — sector, growth profile, business model similarity)
A21: Mamaearth: D2C FMCG, 22% growth, brand-led — most direct comparable. Bikaji: premium Indian snack, similar consumer. Hindustan Foods: FMCG at lower scale. Emami: established health/wellness — mature multiple anchor. Patanjali Foods: Indian wellness brand. All NSE/BSE listed. Source: NSE/BSE market data and annual reports.
A22: AURA IMPLIED VALUATION — Enter your projected figures (blue cells)
A23: AURA Metric | B23: Your Value | D23: Implied EV at Peer Median Mult | F23: Implied Equity Value | G23: Per Share (₹)
A24: AURA FY2025E Revenue (₹cr) | B24: =PROJECTIONS!E21 -> 291.2
A25: AURA FY2025E EBITDA (₹cr) | B25: =PROJECTIONS!E25 -> 37.856
A26: AURA FY2025E PAT (₹cr) | B26: =PROJECTIONS!E32 -> 24.9462
A27: Net Debt (₹cr) | B27: -16 | C27: Derive from FY2024 Balance Sheet: Long-Term Debt (42) minus Cash & Equivalents (28) = 14 (pre-IPO). Post-IPO: Rs. 30 Cr of fresh issue proceeds repay debt, so Long-Term Debt falls to 12 and Net Debt = 12 − 28 = −16 (net cash). State clearly whether you are using pre-IPO or post-IPO net debt and justify your choice.
A28: Shares Outstanding (cr) | B28: 10
A29: AURA IMPLIED SHARE PRICE — Apply peer multiples to AURA projected financials
A30: Method | B30: Applied Multiple | C30: Implied EV (₹cr) | D30: (-) Net Debt (₹cr) | E30: Equity Value (₹cr) | F30: Shares (cr) | G30: Implied Price (₹/share) | H30: Notes / Approach
A31: EV / Revenue | B31: 6.5 | C31: =B24*B31 -> 1892.8 | D31: -16 | E31: =C31-D31 -> 1908.8 | F31: 10 | G31: =E31/F31 -> 190.88 | H31: EV = AURA Revenue × Applied Multiple. Equity Value = EV − Net Debt. Implied Price = Equity Value ÷ Shares Outstanding.
A32: EV / EBITDA | B32: 38 | C32: =B25*B32 -> 1438.528 | D32: -16 | E32: =C32-D32 -> 1454.528 | F32: 10 | G32: =E32/F32 -> 145.4528 | H32: EV = AURA EBITDA × Applied Multiple. Equity Value = EV − Net Debt. Implied Price = Equity Value ÷ Shares Outstanding.
A33: P / E | B33: 37 | C33: N/A | D33: N/A | E33: =B26*B33 -> 923.0094 | F33: 10 | G33: =E33/F33 -> 92.30094 | H33: P/E method: Equity Value = AURA PAT × Applied Multiple. No EV bridge needed. Implied Price = Equity Value ÷ Shares Outstanding.
A37: ANALYST COMMENTARY — Premium or Discount to Peers?
A38: AURA DESERVES A MODERATE PREMIUM to peer median multiples. PREMIUM FACTORS: (1) Revenue CAGR 30% vs peer avg 15% — 2x sector growth; (2) 68% D2C mix = structural gross margin advantage +400-500bps vs trade-dependent peers; (3) NPS 72 vs FMCG avg 45 = documented brand loyalty moat; (4) Asset-light model = higher FCF conversion. DISCOUNT FACTORS: (1) Smaller scale vs Mamaearth/Emami; (2) Founder concentration 61% = key-person risk; (3) Perishables cold-chain exposure; (4) RED FLAG: Debt 91% CAGR vs revenue 41% CAGR — contradicts asset-light narrative. NET CONCLUSION: Applied EV/EBITDA 38x (~3% premium to 37x median). EV/Revenue 6.5x. P/E 37x = at median. SUBSCRIBE at band Rs.42-52.
A44: CONFIDENTIAL | Project Lumina | FinOrbits IB Championship S1

Sheet SUMMARY
A1: VALUATION SUMMARY — PROJECT LUMINA | FINAL RECOMMENDATION
A6: SECTION 1 — VALUATION OUTPUT SUMMARY
A7: Methodology | B7: Low (₹/share) | C7: Base Case (₹/share) | D7: High (₹/share) | E7: Weight % | F7: Weighted Value
A8: DCF Valuation | B8: 38 | C8: 46 | D8: 55 | E8: 0.5 | F8: =C8*E8 -> 23 | G8: Link from DCF tab, Section 4
A9: EV/EBITDA Comps | B9: 32 | C9: 44 | D9: 54 | E9: 0.35 | F9: =C9*E9 -> 15.4 | G9: From Comparables — EBITDA-based
A10: P/E Comps | B10: 28 | C10: 39 | D10: 49 | E10: 0.15 | F10: =C10*E10 -> 5.85 | G10: From Comparables — P/E based
A11: WEIGHTED AVERAGE | B11: =B8*E8+B9*E9+B10*E10 -> 34.4 | C11: =C8*E8+C9*E9+C10*E10 -> 44.25 | D11: =D8*E8+D9*E9+D10*E10 -> 53.75 | E11: 1 | F11: =F8+F9+F10 -> 44.25 | G11: = Sum of (Base x Weight) each method
A14: SECTION 2 — FINAL RECOMMENDATION
A15: IPO Price Band Recommendation (₹/share) | B15: Low: Rs.40 | High: Rs.52
A16: Recommendation | B16: SUBSCRIBE
A17: Upside / Downside to Mid-Band | B17: ~15% upside at mid-band Rs.46 vs weighted base Rs.44.4
A18: Primary Valuation Method Used | B18: Blended — 50% DCF + 35% EV/EBITDA + 15% P/E
A19: Key Assumption Driving Valuation | B19: Revenue growth 30%→18% FY25-29; EBITDA margin 13%→14.8%; Post-IPO Rs.30Cr debt repayment improves ROCE
A20: One Key Risk to Your Thesis | B20: RED FLAG: Debt 91% CAGR vs revenue 41% CAGR contradicts asset-light narrative; Founder concentration 61%
A22: FOOTBALL FIELD VALUATION SUMMARY: DCF: Rs.38 (Low) — Rs.46 (Base) — Rs.55 (High) EV/EBITDA Comps: Rs.32 (Low) — Rs.44 (Base) — Rs.54 (High) P/E Comps: Rs.28 (Low) — Rs.39 (Base) — Rs.49 (High) Weighted Base: Rs.44.4 RECOMMENDED BAND: Rs.40 — Rs.52 | SUBSCRIBE (Chart: Insert > Bar Chart > Stacked Bar. X=share price Rs., Y=methodology. Vertical marker at Rs.46 mid-band in blue #4AACFF. Grey for others.)
A23: SECTION 3 — FOOTBALL FIELD CHART
A24: INSERT YOUR FOOTBALL FIELD CHART HERE How to build it: 1. Create a horizontal bar chart (Insert > Bar Chart > Stacked Bar) 2. X-axis = Share price in ₹. Y-axis = 3 methodologies (DCF, EV/EBITDA, P/E) 3. Each bar shows the range from Low to High for that methodology 4. Add a vertical line or separate series for your recommended price band 5. Color: #4AACFF (blue) for your recommended band. Grey for others. This is the visual centerpiece of your submission deck.
A34: CONFIDENTIAL | Project Lumina | FinOrbits IB Championship S1 | finorbits.com
